2020-10-14 11:43:08,522 DEBUG    root            Loaded Command Group: ['gcloud', 'app']
2020-10-14 11:43:08,556 DEBUG    root            Loaded Command Group: ['gcloud', 'app', 'create']
2020-10-14 11:43:08,558 DEBUG    root            Running [gcloud.app.create] with arguments: [--project: "wolberhello"]
2020-10-14 11:43:09,226 DEBUG    root            (gcloud.app.create) User [colmplang@gmail.com] does not have permission to access apps instance [wolberhello] (or it may not exist): The caller does not have permission
Traceback (most recent call last):
  File "/Users/colmlang/google-cloud-sdk/lib/googlecloudsdk/calliope/cli.py", line 983, in Execute
    resources = calliope_command.Run(cli=self, args=args)
  File "/Users/colmlang/google-cloud-sdk/lib/googlecloudsdk/calliope/backend.py", line 808, in Run
    resources = command_instance.Run(args)
  File "/Users/colmlang/google-cloud-sdk/lib/surface/app/create.py", line 63, in Run
    create_util.CheckAppNotExists(api_client, project)
  File "/Users/colmlang/google-cloud-sdk/lib/googlecloudsdk/command_lib/app/create_util.py", line 54, in CheckAppNotExists
    app = api_client.GetApplication()  # Should raise NotFoundError
  File "/Users/colmlang/google-cloud-sdk/lib/googlecloudsdk/api_lib/app/appengine_api_client.py", line 75, in GetApplication
    return self.client.apps.Get(request)
  File "/Users/colmlang/google-cloud-sdk/lib/googlecloudsdk/third_party/apis/appengine/v1/appengine_v1_client.py", line 1119, in Get
    config, request, global_params=global_params)
  File "/Users/colmlang/google-cloud-sdk/lib/third_party/apitools/base/py/base_api.py", line 731, in _RunMethod
    return self.ProcessHttpResponse(method_config, http_response, request)
  File "/Users/colmlang/google-cloud-sdk/lib/third_party/apitools/base/py/base_api.py", line 737, in ProcessHttpResponse
    self.__ProcessHttpResponse(method_config, http_response, request))
  File "/Users/colmlang/google-cloud-sdk/lib/third_party/apitools/base/py/base_api.py", line 604, in __ProcessHttpResponse
    http_response, method_config=method_config, request=request)
apitools.base.py.exceptions.HttpForbiddenError: HttpError accessing <https://appengine.googleapis.com/v1/apps/wolberhello?alt=json>: response: <{'vary': 'Origin, X-Origin, Referer', 'content-type': 'application/json; charset=UTF-8', 'date': 'Wed, 14 Oct 2020 18:43:09 GMT', 'server': 'ESF', 'cache-control': 'private', 'x-xss-protection': '0', 'x-frame-options': 'SAMEORIGIN', 'x-content-type-options': 'nosniff', 'alt-svc': 'h3-Q050=":443"; ma=2592000,h3-29=":443"; ma=2592000,h3-27=":443"; ma=2592000,h3-T051=":443"; ma=2592000,h3-T050=":443"; ma=2592000,h3-Q046=":443"; ma=2592000,h3-Q043=":443"; ma=2592000,quic=":443"; ma=2592000; v="46,43"', 'transfer-encoding': 'chunked', 'status': '403', 'content-length': '126', '-content-encoding': 'gzip'}>, content <{
  "error": {
    "code": 403,
    "message": "The caller does not have permission",
    "status": "PERMISSION_DENIED"
  }
}
>
2020-10-14 11:43:09,230 ERROR    root            (gcloud.app.create) User [colmplang@gmail.com] does not have permission to access apps instance [wolberhello] (or it may not exist): The caller does not have permission
