2020-10-14 12:43:03,081 DEBUG    root            Loaded Command Group: ['gcloud', 'projects']
2020-10-14 12:43:03,083 DEBUG    root            Loaded Command Group: ['gcloud', 'projects', 'create']
2020-10-14 12:43:03,086 DEBUG    root            Running [gcloud.projects.create] with arguments: [--set-as-default: "True", PROJECT_ID: "colmhello"]
2020-10-14 12:43:03,428 DEBUG    root            (gcloud.projects.create) Project creation failed. The project ID you specified is already in use by another project. Please try an alternative ID.
Traceback (most recent call last):
  File "/Users/colmlang/google-cloud-sdk/lib/surface/projects/create.py", line 135, in Run
    labels=labels)
  File "/Users/colmlang/google-cloud-sdk/lib/googlecloudsdk/api_lib/cloudresourcemanager/projects_api.py", line 104, in Create
    labels=labels))
  File "/Users/colmlang/google-cloud-sdk/lib/googlecloudsdk/third_party/apis/cloudresourcemanager/v1/cloudresourcemanager_v1_client.py", line 707, in Create
    config, request, global_params=global_params)
  File "/Users/colmlang/google-cloud-sdk/lib/third_party/apitools/base/py/base_api.py", line 731, in _RunMethod
    return self.ProcessHttpResponse(method_config, http_response, request)
  File "/Users/colmlang/google-cloud-sdk/lib/third_party/apitools/base/py/base_api.py", line 737, in ProcessHttpResponse
    self.__ProcessHttpResponse(method_config, http_response, request))
  File "/Users/colmlang/google-cloud-sdk/lib/third_party/apitools/base/py/base_api.py", line 604, in __ProcessHttpResponse
    http_response, method_config=method_config, request=request)
apitools.base.py.exceptions.HttpConflictError: HttpError accessing <https://cloudresourcemanager.googleapis.com/v1/projects?alt=json>: response: <{'vary': 'Origin, X-Origin, Referer', 'content-type': 'application/json; charset=UTF-8', 'date': 'Wed, 14 Oct 2020 19:43:03 GMT', 'server': 'ESF', 'cache-control': 'private', 'x-xss-protection': '0', 'x-frame-options': 'SAMEORIGIN', 'x-content-type-options': 'nosniff', 'server-timing': 'gfet4t7; dur=188', 'alt-svc': 'h3-Q050=":443"; ma=2592000,h3-29=":443"; ma=2592000,h3-27=":443"; ma=2592000,h3-T051=":443"; ma=2592000,h3-T050=":443"; ma=2592000,h3-Q046=":443"; ma=2592000,h3-Q043=":443"; ma=2592000,quic=":443"; ma=2592000; v="46,43"', 'transfer-encoding': 'chunked', 'status': '409', 'content-length': '119', '-content-encoding': 'gzip'}>, content <{
  "error": {
    "code": 409,
    "message": "Requested entity already exists",
    "status": "ALREADY_EXISTS"
  }
}
>

During handling of the above exception, another exception occurred:

Traceback (most recent call last):
  File "/Users/colmlang/google-cloud-sdk/lib/googlecloudsdk/calliope/cli.py", line 983, in Execute
    resources = calliope_command.Run(cli=self, args=args)
  File "/Users/colmlang/google-cloud-sdk/lib/googlecloudsdk/calliope/backend.py", line 808, in Run
    resources = command_instance.Run(args)
  File "/Users/colmlang/google-cloud-sdk/lib/surface/projects/create.py", line 140, in Run
    core_exceptions.reraise(exceptions.HttpException(msg))
  File "/Users/colmlang/google-cloud-sdk/lib/googlecloudsdk/core/exceptions.py", line 146, in reraise
    six.reraise(type(exc_value), exc_value, tb)
  File "/Users/colmlang/google-cloud-sdk/lib/third_party/six/__init__.py", line 692, in reraise
    raise value.with_traceback(tb)
  File "/Users/colmlang/google-cloud-sdk/lib/surface/projects/create.py", line 135, in Run
    labels=labels)
  File "/Users/colmlang/google-cloud-sdk/lib/googlecloudsdk/api_lib/cloudresourcemanager/projects_api.py", line 104, in Create
    labels=labels))
  File "/Users/colmlang/google-cloud-sdk/lib/googlecloudsdk/third_party/apis/cloudresourcemanager/v1/cloudresourcemanager_v1_client.py", line 707, in Create
    config, request, global_params=global_params)
  File "/Users/colmlang/google-cloud-sdk/lib/third_party/apitools/base/py/base_api.py", line 731, in _RunMethod
    return self.ProcessHttpResponse(method_config, http_response, request)
  File "/Users/colmlang/google-cloud-sdk/lib/third_party/apitools/base/py/base_api.py", line 737, in ProcessHttpResponse
    self.__ProcessHttpResponse(method_config, http_response, request))
  File "/Users/colmlang/google-cloud-sdk/lib/third_party/apitools/base/py/base_api.py", line 604, in __ProcessHttpResponse
    http_response, method_config=method_config, request=request)
googlecloudsdk.calliope.exceptions.HttpException: Project creation failed. The project ID you specified is already in use by another project. Please try an alternative ID.
2020-10-14 12:43:03,432 ERROR    root            (gcloud.projects.create) Project creation failed. The project ID you specified is already in use by another project. Please try an alternative ID.
